Workbook
Name channel: Data!$F$2:$F$108
Name month: Data!$H$2:$H$108
Name month_sold: Data!$H$2:$H$108
Name product: Data!$E$2:$E$108
Name quantity: Data!$I$2:$I$108
Name revenue: Data!$K$2:$K$108
Name SALES_CHANNEL: Data!$F$2:$F$108
Name Slicer_Country: #N/A
Name Slicer_Months__Date_Sold: #N/A
Name Slicer_Product: #N/A
Name Slicer_Sales_Channel: #N/A
Name zz: 'Part 1'!$G$2:$G$33

Sheet Sheet3
A1: World Cup 2014 | C1: World Cup 2010 | E1: World Cup 2006 | G1: World Cup 2002
A2: Player name | B2: Goals | C2: Player name | D2: Goals | E2: Player name | F2: Goals | G2: Player name | H2: Goals
A3: James Rodríguez | B3: 6 | C3: Thomas Müller | D3: 5 | E3: Miroslav Klose | F3: 5 | G3: Ronaldo | H3: 8
A4: Thomas Müller | B4: 5 | C4: Wesley Sneijder | D4: 5 | E4: Hernán Crespo | F4: 3 | G4: Rivaldo | H4: 5
A5: Lionel Messi | B5: 4 | C5: David Villa | D5: 5 | E5: Maxi Rodríguez | F5: 3 | G5: Miroslav Klose | H5: 5
A6: Neymar | B6: 4 | C6: Diego Forlán | D6: 5 | E6: Ronaldo | F6: 3 | G6: Jon Dahl Tomasson | H6: 4
A7: Robin van Persie | B7: 4 | C7: Gonzalo Higuaín | D7: 4 | E7: Thierry Henry | F7: 3 | G7: Christian Vieri | H7: 4
A8: Enner Valencia | B8: 3 | C8: Miroslav Klose | D8: 4 | E8: Zinedine Zidane | F8: 3 | G8: Michael Ballack | H8: 3
A9: Karim Benzema | B9: 3 | C9: Róbert Vittek | D9: 4 | E9: Lukas Podolski | F9: 3 | G9: Marc Wilmots | H9: 3
A10: André Schürrle | B10: 3 | C10: Luís Fabiano | D10: 3 | E10: Fernando Torres | F10: 3 | G10: Pauleta | H10: 3
A11: Arjen Robben | B11: 3 | C11: Asamoah Gyan | D11: 3 | E11: David Villa | F11: 3 | G11: Robbie Keane | H11: 3
A12: Xherdan Shaqiri | B12: 3 | C12: Landon Donovan | D12: 3 | E12: Tim Cahill | F12: 2 | G12: Papa Bouba Diop | H12: 3
A13: Abdelmoumene Djabou | B13: 2 | C13: Luis Suárez | D13: 3 | E13: Adriano | F13: 2 | G13: Fernando Morientes | H13: 3
A14: Islam Slimani | B14: 2 | C14: Carlos Tevez | D14: 2 | E14: Paulo Wanchope | F14: 2 | G14: Raúl | H14: 3
... A100: Silvestre Varela | B100: 1 | C100: Park Chu-young | D100: 1 | E100: Philippe Senderos | F100: 1 | G100: Emre Belözoğlu | H100: 1
A101: Aleksandr Kerzhakov | B101: 1 | E101: Mohamed Kader | F101: 1 | G101: Bülent Korkmaz | H101: 1
A102: Aleksandr Kokorin | B102: 1 | E102: Radhi Jaïdi | F102: 1 | G102: Hakan Şükür | H102: 1
A103: Koo Ja-cheol | B103: 1 | E103: Ziad Jaziri | F103: 1 | G103: Clint Mathis | H103: 1
A104: Lee Keun-ho | B104: 1 | E104: Jawhar Mnari | F104: 1 | G104: John O'Brien | H104: 1
A105: Son Heung-min | B105: 1 | E105: Maksym Kalynychenko | F105: 1 | G105: Diego Forlán | H105: 1
A106: Xabi Alonso | B106: 1 | E106: Serhiy Rebrov | F106: 1 | G106: Richard Morales | H106: 1
A107: Juan Mata | B107: 1 | E107: Andriy Rusol | F107: 1 | G107: Álvaro Recoba | H107: 1
A108: Fernando Torres | B108: 1 | E108: Clint Dempsey | F108: 1 | G108: Darío Rodríguez | H108: 1
A109: David Villa | B109: 1 | E109: Cristian Zaccardo | F109: 1 | G109: Jorge Costa | H109: 1
A110: Blerim Džemaili | B110: 1 | E110: Carlos Gamarra | F110: 1 | G110: Carles Puyol | H110: 1
A111: Admir Mehmedi | B111: 1 | E111: Petit | F111: 1 | G111: Jeff Agoos | H111: 1
A112: Haris Seferović | B112: 1 | E112: Brent Sancho | F112: 1
A113: Granit Xhaka | B113: 1
A114: John Brooks | B114: 1
A115: Julian Green | B115: 1
A116: Jermaine Jones | B116: 1
A117: Edinson Cavani | B117: 1
A118: Diego Godín | B118: 1
A119: Sead Kolašinac | B119: 1
A120: Marcelo | B120: 1
A121: John Boye | B121: 1
A122: Noel Valladares | B122: 1
A123: Joseph Yobo | B123: 1

Sheet Part 1
B1: No | C1: Name | D1: Nationality | E1: DOB | F1: Age
B2: 1 | C2: Kiko Casilla | D2: Spain | E2: 1986 | F2: =2025-E2 -> 39
B3: 2 | C3: Mohamet Ramos | D3: Spain | E3: 2000 | F3: =2025-E3 -> 25
B4: 3 | C4: Keylor Navas | D4: Costa Rica | E4: 1986 | F4: =2025-E4 -> 39
B5: 4 | C5: Luca Zidane | D5: France | E5: 1998 | F5: =2025-E5 -> 27 | H5: average age of Real Madrid players | I5: =AVERAGE(F2:F33) -> 31.875
B6: 5 | C6: Álvaro Tejero | D6: Spain | E6: 1996 | F6: =2025-E6 -> 29
B7: 6 | C7: Dani Carvajal | D7: Spain | E7: 1992 | F7: =2025-E7 -> 33
B8: 7 | C8: Achraf Hakimi | D8: Morocco | E8: 1998 | F8: =2025-E8 -> 27
B9: 8 | C9: Theo Hernández | D9: France | E9: 1997 | F9: =2025-E9 -> 28
B10: 9 | C10: Manu Hernando | D10: Spain | E10: 1998 | F10: =2025-E10 -> 27
B11: 10 | C11: Marcelo | D11: Brazil | E11: 1988 | F11: =2025-E11 -> 37
B12: 11 | C12: Nacho | D12: Spain | E12: 1990 | F12: =2025-E12 -> 35
B13: 12 | C13: Quezada | D13: Dom. Republic | E13: 1996 | F13: =2025-E13 -> 29
B14: 13 | C14: Sergio Ramos | D14: Spain | E14: 1986 | F14: =2025-E14 -> 39
B15: 14 | C15: Vallejo | D15: Spain | E15: 1997 | F15: =2025-E15 -> 28
B16: 15 | C16: Raphaël Varane | D16: France | E16: 1993 | F16: =2025-E16 -> 32
B17: 16 | C17: Casemiro | D17: Brazil | E17: 1992 | F17: =2025-E17 -> 33
... B33: 32 | C33: Lucas Vázquez | D33: Spain | E33: 1991 | F33: =2025-E33 -> 34

Sheet Part 2
B4: Q | C4: P | F4: 10 | G4: 20 | H4: 30 | I4: 40 | J4: 50 | K4: 60
B5: 50 | C5: 10 | E5: 50 | F5: =F$4*$E5 -> 500 | G5: =G$4*$E5 -> 1000 | H5: =H$4*$E5 -> 1500 | I5: =I$4*$E5 -> 2000 | J5: =J$4*$E5 -> 2500 | K5: =K$4*$E5 -> 3000
B6: 100 | C6: 20 | E6: 100 | F6: =F$4*$E6 -> 1000 | G6: =G$4*$E6 -> 2000 | H6: =H$4*$E6 -> 3000 | I6: =I$4*$E6 -> 4000 | J6: =J$4*$E6 -> 5000 | K6: =K$4*$E6 -> 6000
B7: 150 | C7: 30 | E7: 150 | F7: =F$4*$E7 -> 1500 | G7: =G$4*$E7 -> 3000 | H7: =H$4*$E7 -> 4500 | I7: =I$4*$E7 -> 6000 | J7: =J$4*$E7 -> 7500 | K7: =K$4*$E7 -> 9000 | N7: sum of revenue combinations | O7: =SUM(F5:K14) -> 577500
B8: 200 | C8: 40 | E8: 200 | F8: =F$4*$E8 -> 2000 | G8: =G$4*$E8 -> 4000 | H8: =H$4*$E8 -> 6000 | I8: =I$4*$E8 -> 8000 | J8: =J$4*$E8 -> 10000 | K8: =K$4*$E8 -> 12000 | N8: average of revenue combinations | O8: =AVERAGE(F5:K14) -> 9625
B9: 250 | C9: 50 | E9: 250 | F9: =F$4*$E9 -> 2500 | G9: =G$4*$E9 -> 5000 | H9: =H$4*$E9 -> 7500 | I9: =I$4*$E9 -> 10000 | J9: =J$4*$E9 -> 12500 | K9: =K$4*$E9 -> 15000 | N9: count of revenue combinations | O9: =COUNT(F5:K14) -> 60
B10: 300 | C10: 60 | E10: 300 | F10: =F$4*$E10 -> 3000 | G10: =G$4*$E10 -> 6000 | H10: =H$4*$E10 -> 9000 | I10: =I$4*$E10 -> 12000 | J10: =J$4*$E10 -> 15000 | K10: =K$4*$E10 -> 18000
B11: 350 | E11: 350 | F11: =F$4*$E11 -> 3500 | G11: =G$4*$E11 -> 7000 | H11: =H$4*$E11 -> 10500 | I11: =I$4*$E11 -> 14000 | J11: =J$4*$E11 -> 17500 | K11: =K$4*$E11 -> 21000
B12: 400 | E12: 400 | F12: =F$4*$E12 -> 4000 | G12: =G$4*$E12 -> 8000 | H12: =H$4*$E12 -> 12000 | I12: =I$4*$E12 -> 16000 | J12: =J$4*$E12 -> 20000 | K12: =K$4*$E12 -> 24000
B13: 450 | E13: 450 | F13: =F$4*$E13 -> 4500 | G13: =G$4*$E13 -> 9000 | H13: =H$4*$E13 -> 13500 | I13: =I$4*$E13 -> 18000 | J13: =J$4*$E13 -> 22500 | K13: =K$4*$E13 -> 27000
B14: 500 | E14: 500 | F14: =F$4*$E14 -> 5000 | G14: =G$4*$E14 -> 10000 | H14: =H$4*$E14 -> 15000 | I14: =I$4*$E14 -> 20000 | J14: =J$4*$E14 -> 25000 | K14: =K$4*$E14 -> 30000

Sheet Data
A1: Distributor ID | B1: Distributor Name | C1: Country | D1: Product Code | E1: Product | F1: Sales Channel | G1: Date Sold | H1: Month Sold | I1: Quantity | J1: Unit Price | K1: Revenue
A2: 23345 | B2: Devin Abbott | C2: France | D2: SUPA105 | E2: Super Soft Bulk - 2 Litres | F2: Online | G2: 41150 | H2: =VALUE(MONTH(G2)) -> 8 | I2: 208 | J2: 14.5 | K2: =J2*I2 -> 3016
A3: 23278 | B3: Aphrodite Brennan | C3: Malawi | D3: SUPA105 | E3: Super Soft Bulk - 2 Litres | F3: Direct | G3: 41145 | H3: =VALUE(MONTH(G3)) -> 8 | I3: 197 | J3: 14.5 | K3: =J3*I3 -> 2856.5
A4: 23303 | B4: Guinevere Key | C4: Colombia | D4: SUPA105 | E4: Super Soft Bulk - 2 Litres | F4: Retail | G4: 41138 | H4: =VALUE(MONTH(G4)) -> 8 | I4: 176 | J4: 14.5 | K4: =J4*I4 -> 2552
A5: 23353 | B5: Zahir Fields | C5: Canada | D5: SUPA105 | E5: Super Soft Bulk - 2 Litres | F5: Direct | G5: 41070 | H5: =VALUE(MONTH(G5)) -> 6 | I5: 168 | J5: 14.5 | K5: =J5*I5 -> 2436
A6: 23289 | B6: Deacon Craig | C6: Mongolia | D6: SUPA105 | E6: Super Soft Bulk - 2 Litres | F6: Retail | G6: 41123 | H6: =VALUE(MONTH(G6)) -> 8 | I6: 166 | J6: 14.5 | K6: =J6*I6 -> 2407
A7: 23378 | B7: Brynne Mcgowan | C7: Finland | D7: SUPA105 | E7: Super Soft Bulk - 2 Litres | F7: Online | G7: 41078 | H7: =VALUE(MONTH(G7)) -> 6 | I7: 157 | J7: 14.5 | K7: =J7*I7 -> 2276.5
A8: 23283 | B8: Lani Sweet | C8: Vanuatu | D8: SUPA105 | E8: Super Soft Bulk - 2 Litres | F8: Online | G8: 41084 | H8: =VALUE(MONTH(G8)) -> 6 | I8: 142 | J8: 14.5 | K8: =J8*I8 -> 2059
A9: 23324 | B9: Noble Warner | C9: Burkina Faso | D9: SUPA104 | E9: Super Soft - 1 Litre | F9: Retail | G9: 41134 | H9: =VALUE(MONTH(G9)) -> 8 | I9: 193 | J9: 9.99 | K9: =J9*I9 -> 1928.07
A10: 23264 | B10: Levi Douglas | C10: Tanzania, United Republic of | D10: DETA800 | E10: Detafast Stain Remover - 800ml | F10: Online | G10: 41139 | H10: =VALUE(MONTH(G10)) -> 8 | I10: 205 | J10: 9 | K10: =J10*I10 -> 1845
A11: 23291 | B11: Jelani Odonnell | C11: Albania | D11: DETA800 | E11: Detafast Stain Remover - 800ml | F11: Retail | G11: 41139 | H11: =VALUE(MONTH(G11)) -> 8 | I11: 199 | J11: 9 | K11: =J11*I11 -> 1791
A12: 23305 | B12: Jared Sandoval | C12: Botswana | D12: DETA800 | E12: Detafast Stain Remover - 800ml | F12: Online | G12: 41147 | H12: =VALUE(MONTH(G12)) -> 8 | I12: 188 | J12: 9 | K12: =J12*I12 -> 1692
A13: 23350 | B13: Hiroko Acevedo | C13: Burundi | D13: DETA800 | E13: Detafast Stain Remover - 800ml | F13: Online | G13: 41085 | H13: =VALUE(MONTH(G13)) -> 6 | I13: 188 | J13: 9 | K13: =J13*I13 -> 1692
... A108: 23279 | B108: Angela Wise | C108: Moldova | D108: PURA100 | E108: Pure Soft Detergent - 100ml | F108: Online | G108: 41020 | H108: =VALUE(MONTH(G108)) -> 4 | I108: 10 | J108: 3 | K108: =J108*I108 -> 30

Sheet VLOOKUP
A1: Players who scored five or more goals in the Fifa World Cup
A2: Plyaer name | B2: Team | C2: Goals | D2: Matches | E2: Cups
A3: Ademir | B3: Brazil | C3: 8 | D3: 6 | E3: 1 | H3: Plyaer name | I3: Goals | J3: Matches
A4: Alessandro Altobelli | B4: Italy | C4: 5 | D4: 7 | E4: 2 | H4: Diego Maradona | I4: =VLOOKUP($H$4,Table2[],3,0) -> 8 | J4: =VLOOKUP($H4,Table2[],4,0) -> 21
A5: Andrzej Szarmach | B5: Poland | C5: 7 | D5: 13 | E5: 3 | H5: Lionel Messi | I5: =VLOOKUP(H5,Table2[],3,0) -> 5 | J5: =VLOOKUP($H5,Table2[],4,0) -> 14
A6: Arjen Robben | B6: Netherlands | C6: 6 | D6: 15 | E6: 3 | H6: Ronaldo | I6: =VLOOKUP(H6,Table2[],3,0) -> 15 | J6: =VLOOKUP($H6,Table2[],4,0) -> 19
A7: Asamoah Gyan | B7: Ghana | C7: 6 | D7: 11 | E7: 3 | H7: Thierry Henry | I7: =VLOOKUP(H7,Table2[],3,0) -> 6 | J7: =VLOOKUP($H7,Table2[],4,0) -> 17
A8: Bebeto | B8: Brazil | C8: 6 | D8: 15 | E8: 3 | H8: Thomas Müller | I8: =VLOOKUP(H8,Table2[],3,0) -> 10 | J8: =VLOOKUP($H8,Table2[],4,0) -> 13
A9: Careca | B9: Brazil | C9: 7 | D9: 9 | E9: 2 | H9: Zinedine Zidane | I9: =VLOOKUP(H9,Table2[],3,0) -> 5 | J9: =VLOOKUP($H9,Table2[],4,0) -> 12
A10: Christian Vieri | B10: Italy | C10: 9 | D10: 9 | E10: 2 | H10: Pelé | I10: =VLOOKUP(H10,Table2[],3,0) -> 12 | J10: =VLOOKUP($H10,Table2[],4,0) -> 14
A11: David Villa | B11: Spain | C11: 9 | D11: 12 | E11: 3 | H11: Raúl | I11: =VLOOKUP(H11,Table2[],3,0) -> 5 | J11: =VLOOKUP($H11,Table2[],4,0) -> 11
A12: Davor Šuker | B12: Croatia | C12: 6 | D12: 8 | E12: 3
A13: Dennis Bergkamp | B13: Netherlands | C13: 6 | D13: 12 | E13: 2
A14: Diego Forlán | B14: Uruguay | C14: 6 | D14: 10 | E14: 3
A15: Diego Maradona | B15: Argentina | C15: 8 | D15: 21 | E15: 4
A16: Emilio Butragueño | B16: Spain | C16: 5 | D16: 9 | E16: 2
A17: Erich Probst | B17: Austria | C17: 6 | D17: 5 | E17: 1
A18: Eusébio | B18: Portugal | C18: 9 | D18: 6 | E18: 1
A19: Fernando Hierro | B19: Spain | C19: 5 | D19: 12 | E19: 4
A20: Fernando Morientes | B20: Spain | C20: 5 | D20: 7 | E20: 2
A21: Franz Beckenbauer | B21: West Germany | C21: 5 | D21: 18 | E21: 3
A22: Gabriel Batistuta | B22: Argentina | C22: 10 | D22: 12 | E22: 3
A23: Garrincha | B23: Brazil | C23: 5 | D23: 12 | E23: 3
... A92: Zinedine Zidane | B92: France | C92: 5 | D92: 12 | E92: 3

Sheet LOGICAL FUNCTIONS
C1: from (Data) sheet
C4: Product | D4: Count of sales | F4: Sales Channel | G4: Count of sales
C5: Pure Soft Detergent - 100ml | D5: =COUNTIF(product,C5) -> 11 | F5: Online | G5: =COUNTIF(Data!F2:F108,F5) -> 52
C6: Pure Soft Detergent - 200ml | D6: =COUNTIF(product,C6) -> 11 | F6: Direct | G6: =COUNTIF(Data!F3:F109,F6) -> 9
C7: Pure Soft Detergent - 250ml | D7: =COUNTIF(product,C7) -> 11 | F7: Retail | G7: =COUNTIF(Data!F4:F110,F7) -> 46
C8: Pure Soft Detergent - 500ml | D8: =COUNTIF(product,C8) -> 6
C9: Detafast Stain Remover - 100ml | D9: =COUNTIF(product,C9) -> 8 | F9: Sales Channel | G9: Count of sales | H9: Super Soft Bulk - 2 Litres
C10: Detafast Stain Remover - 200ml | D10: =COUNTIF(product,C10) -> 8 | F10: Online | G10: =COUNTIFS(channel,F10,product,$H$9) -> 4
C11: Detafast Stain Remover - 800ml | D11: =COUNTIF(product,C11) -> 12 | F11: Direct | G11: =COUNTIFS(channel,F11,product,$H$9) -> 2
C12: Super Soft - 250ml | D12: =COUNTIF(product,C12) -> 7 | F12: Retail | G12: =COUNTIFS(channel,F12,product,$H$9) -> 5
C13: Super Soft - 500ml | D13: =COUNTIF(product,C13) -> 11
C14: Super Soft - 1 Litre | D14: =COUNTIF(product,C14) -> 11 | G14: Greater than $1000 | H14: Less than $1000 | I14: Equals $1000 | J14: Does not Equal $1000
C15: Super Soft Bulk - 2 Litres | D15: =COUNTIF(product,C15) -> 11 | F15: Sales revenue | G15: =COUNTIF(revenue,">1000") -> 27 | H15: =COUNTIF(revenue,"<1000") -> 80 | I15: =COUNTIF(revenue,"=1000") -> 0 | J15: =COUNTIF(revenue,"<1000") -> 80
C19: Product | D19: Online | E19: Direct | F19: Retail | H19: Total Revenue (Quantity < 100)
C20: Pure Soft Detergent - 100ml | H20: =SUMIF(Data!I2:I108,"<100",Data!K2:K108) -> 16819.62
C21: Pure Soft Detergent - 200ml | K21: Sum of Revenue | L21: Sales Channel
C22: Pure Soft Detergent - 250ml | H22: Total Revenue in August | K22: Product | L22: Online | M22: Direct | N22: Retail
C23: Pure Soft Detergent - 500ml | H23: =SUMIF(Data!H2:H108,8,Data!K2:K108) -> 33326.98 | K23: Detafast Stain Remover - 100ml | L23: 1272 | M23: 750 | N23: 2682
C24: Detafast Stain Remover - 100ml | K24: Detafast Stain Remover - 200ml | L24: 2424.5 | M24: 461.5 | N24: 1963
C25: Detafast Stain Remover - 200ml | K25: Detafast Stain Remover - 800ml | L25: 11385 | N25: 4500
C26: Detafast Stain Remover - 800ml | K26: Pure Soft Detergent - 100ml | L26: 1749 | N26: 1275
C27: Super Soft - 250ml | K27: Pure Soft Detergent - 200ml | L27: 3487.26 | N27: 1484.28
C28: Super Soft - 500ml | D28: =SUMIFS(revenue,product,C28,channel,$D$19) -> 3767.61 | K28: Pure Soft Detergent - 250ml | L28: 549 | M28: 1849.5 | N28: 3708
C29: Super Soft - 1 Litre | K29: Pure Soft Detergent - 500ml | L29: 1527.5 | N29: 1118
C30: Super Soft Bulk - 2 Litres | K30: Super Soft - 1 Litre | L30: 2847.15 | M30: 1408.59 | N30: 5054.94
K31: Super Soft - 250ml | L31: 382.5 | N31: 2659.5
K32: Super Soft - 500ml | L32: 3767.61 | M32: 594.15 | N32: 2705.13
K33: Super Soft Bulk - 2 Litres | L33: 8410 | M33: 5292.5 | N33: 7235.5
C34: Target Revenue | D34: 450 | F34: Identify if the product sales have met the target revenue or not.
C36: Product | D36: Region | E36: QTY | F36: Unit Price | G36: Revenue | H36: Analysis
C37: Super Soft - 1 Litre | D37: North America | E37: 100 | F37: 4.5 | G37: 450 | H37: =IF(G37>=$D$34,"Target Reached","Target Missed") -> Target Reached
C38: Detafast Stain Remover - 200ml | D38: South Asia | E38: 75 | F38: 13 | G38: 975 | H38: =IF(G38>=$D$34,"Target Reached","Target Missed") -> Target Reached
C39: Super Soft Bulk - 2 Litres | D39: Pacific Islands | E39: 13 | F39: 25 | G39: 325 | H39: =IF(G39>=$D$34,"Target Reached","Target Missed") -> Target Missed
C40: Detafast Stain Remover - 800ml | D40: Africa | E40: 200 | F40: 0.75 | G40: 150 | H40: =IF(G40>=$D$34,"Target Reached","Target Missed") -> Target Missed
C41: Pure Soft Detergent - 250ml | D41: Eastern Europe | E41: 11 | F41: 55 | G41: 605 | H41: =IF(G41>=$D$34,"Target Reached","Target Missed") -> Target Reached
C43: Target Unit Price | D43: 4
F44: Identify if the product sales have met the target price and revenue.
C45: Target Revenue | D45: 605
C47: Product | D47: Region | E47: QTY | F47: Unit Price | G47: Revenue | H47: Analysis
C48: Super Soft - 1 Litre | D48: North America | E48: 100 | F48: 4.5 | G48: 450 | H48: =IF(AND(F48>=$D$43,G48>=$D$45),"Reached","Missed") -> Missed
...

Sheet Pivot Tables Analysis
A1: Total Revenue | B1: Avg Price | C1: Total Quantity Sold | D1: #Distributers | F1: Sales Channel Analysis(T-REV vs T-QTY) | J1: Monthly Sales | P1: Row Labels | Q1: Sum of Quantity
A2: 82543.11 | B2: 7.0202804 | C2: 11376 | D2: 107 | F2: Sales Channel | G2: Total Revenue | H2: T-Quantity | J2: Month Name | K2: Total Revenue | L2: Total Quantity | P2: 3 | Q2: 1008
F3: Online | G3: 37801.52 | H3: 5153 | J3: Jan | K3: 8818.49 | L3: 1046 | P3: 3.99 | Q3: 1246
F4: Retail | G4: 34385.35 | H4: 5025 | J4: Feb | K4: 2669.25 | L4: 524 | P4: 4.5 | Q4: 2033
A5: =A1 -> Total Revenue | B5: =B1 -> Avg Price | C5: =C1 -> Total Quantity Sold | D5: =D1 -> #Distributers | F5: Direct | G5: 10356.24 | H5: 1198 | J5: Apr | K5: 871.65 | L5: 231 | P5: 6 | Q5: 784
A6: =A2 -> 82543.11 | B6: =B2 -> 7.0202804 | C6: =C2 -> 11376 | D6: =D2 -> 107 | F6: Grand Total | G6: 82543.11 | H6: 11376 | J6: Jun | K6: 22614.98 | L6: 3004 | P6: 6.5 | Q6: 1153
J7: Jul | K7: 12389.34 | L7: 2190 | P7: 6.99 | Q7: 1011
J8: Aug | K8: 33326.98 | L8: 3988 | P8: 9 | Q8: 1765
A9: Revenue by Channel % | F9: Sales Channel Analysis(T-REV vs T-QTY) | J9: Dec | K9: 1852.42 | L9: 393 | P9: 9.99 | Q9: 932
A10: Sales Channel | B10: Total Revenue | F10: Sales Channel | G10: Total Quantity | J10: Grand Total | K10: 82543.11 | L10: 11376 | P10: 14.5 | Q10: 1444
A11: Direct | B11: 0.12546462 | F11: Online | G11: 5153 | P11: (blank)
A12: Online | B12: 0.45796094 | F12: Retail | G12: 5025 | P12: Grand Total | Q12: 11376
A13: Retail | B13: 0.41657444 | F13: Direct | G13: 1198
A14: Grand Total | B14: 1 | F14: Grand Total | G14: 11376 | J14: Top 10 Performers | P14: Row Labels | Q14: Sum of Quantity
J15: Distributors | K15: Total Revenue | P15: 3 | Q15: 1008
J16: Aphrodite Brennan | K16: 2856.5 | P16: 3.99 | Q16: 1246
A17: Top 5 Products By Revenue | F17: Sales By Products Contribution | J17: Brynne Mcgowan | K17: 2276.5 | P17: 4.5 | Q17: 2033
A18: Product | B18: Total Revenue | F18: Product | G18: Total Revenue | J18: Deacon Craig | K18: 2407 | P18: 6 | Q18: 784
A19: Super Soft Bulk - 2 Litres | B19: 20938 | F19: Super Soft Bulk - 2 Litres | G19: 0.25366139 | J19: Devin Abbott | K19: 3016 | P19: 6.5 | Q19: 1153
A20: Detafast Stain Remover - 800ml | B20: 15885 | F20: Detafast Stain Remover - 800ml | G20: 0.19244489 | J20: Jelani Odonnell | K20: 1791 | P20: 6.99 | Q20: 1011
A21: Super Soft - 1 Litre | B21: 9310.68 | F21: Super Soft - 1 Litre | G21: 0.11279779 | J21: Lani Sweet | K21: 2059 | P21: 9 | Q21: 1765
A22: Super Soft - 500ml | B22: 7066.89 | F22: Super Soft - 500ml | G22: 0.085614535 | J22: Levi Douglas | K22: 1845 | P22: 9.99 | Q22: 932
A23: Pure Soft Detergent - 250ml | B23: 6106.5 | F23: Pure Soft Detergent - 250ml | G23: 0.073979524 | J23: Noble Warner | K23: 1928.07 | P23: 14.5 | Q23: 1444
A24: Grand Total | B24: 59307.07 | F24: Pure Soft Detergent - 200ml | G24: 0.060229618 | J24: Guinevere Key | K24: 2552 | P24: (blank)
F25: Detafast Stain Remover - 200ml | G25: 0.058745061 | J25: Zahir Fields | K25: 2436
F26: Detafast Stain Remover - 100ml | G26: 0.056988403 | J26: Grand Total | K26: 23167.07
F27: Super Soft - 250ml | G27: 0.03685347
F28: Pure Soft Detergent - 100ml | G28: 0.036635402
F29: Pure Soft Detergent - 500ml | G29: 0.032049919
F30: Grand Total | G30: 1
A32: Top 5 Countries By Sales
A33: Country | B33: Total Revenue | C33: Total Quantity
A34: France | B34: 3016 | C34: 208
A35: Malawi | B35: 2856.5 | C35: 197 | F35: Monthly Sales
A36: Canada | B36: 2845.59 | C36: 209 | F36: Month Name | G36: Total Revenue | H36: %Growth
A37: Burkina Faso | B37: 2628.27 | C37: 332 | F37: Jan | G37: 8818.49
A38: Colombia | B38: 2552 | C38: 176 | F38: Feb | G38: 2669.25 | H38: -0.69731212
A39: Grand Total | B39: 13898.36 | C39: 1122 | F39: Apr | G39: 871.65 | H39: -0.6734476
F40: Jun | G40: 22614.98 | H40: 24.945024
F41: Jul | G41: 12389.34 | H41: -0.45216224
...

Sheet Dashboard
